import pytest


@pytest.mark.skip(reason="shall be restored")
def test_unique(config):
    # Update: There is no global and local diff
    # everything is considered as global now
    # *************** global unique ****************
    # Two similar objects with same Name.
    config.w_list.wobject(w_name="global_unique_similar_obj")
    config.w_list.wobject(w_name="global_unique_similar_obj")
    try:
        config.validate()
        pytest.fail("validation failed")
    except Exception as e:
        if "global_unique_similar_obj already exists" not in str(e):
            pytest.fail("global_unique_similar_obj validation failed")

    # Two similar objects with different name
    config.w_list[1].w_name = "global_unique_similar_obj1"
    config.validate()

    # Two different objects with same name
    config.name = "global_unique"
    config.w_list.wobject(w_name="global_unique")
    try:
        config.validate()
        pytest.fail("validation failed")
    except Exception as e:
        if "global_unique already exists" not in str(e):
            pytest.fail("global_unique validation failed")

    #  Two different objects with different name
    config.name = "global_unique1"
    config.validate()

    # *************** local unique ****************
    # Two similar objects with same Name.
    config.x_list.zobject(name="local_unique_similar")
    config.x_list.zobject(name="local_unique_similar")
    try:
        config.validate()
        pytest.fail("validation failed")
    except Exception as e:
        if "local_unique_similar already exists" not in str(e):
            pytest.fail("local_unique_similar validation failed")

    # Two similar objects with different name
    config.x_list[1].name = "local_unique_similar1"
    config.validate()

    # Two different objects with same name
    config.name = "local_global_mix"
    config.x_list.zobject(name="local_global_mix")
    try:
        config.validate()
        pytest.fail("validation failed")
    except Exception as e:
        if "local_global_mix already exists" not in str(e):
            pytest.fail("local_unique_similar validation failed")
    try:
        config.serialize()
        pytest.fail("serialization failed")
    except Exception as e:
        if "local_global_mix already exists" not in str(e):
            pytest.fail("local_unique_similar validation failed")
    # **********************************************

    # config.z_object.name = "local_unique"
    # config.y_object.y_name = "123"
    # config.x_list.zobject(name="local_unique")
    # try:
    #     config.validate()
    # except Exception as e:
    #     if "local_unique already exists" not in str(
    #         e
    #     ) or "y_name is not a valid type" not in str(e):
    #         pytest.fail("validation failed")
    # try:
    #     config.serialize()
    # except Exception as e:
    #     if "local_unique already exists" not in str(
    #         e
    #     ) or "y_name is not a valid type" not in str(e):
    #         pytest.fail("validation failed")

    # config.x_list[0].name = "local_unique_1"
    # config.y_object.y_name = "local_unique_1"
    # data = config.serialize(config.DICT)
    # data["y_object"]["y_name"] = "local_unique_decode"
    # data["z_object"]["name"] = "local_unique_decode"
    # try:
    #     config.deserialize(data)
    # except Exception as e:
    #     if "local_unique_decode already exists" not in str(
    #         e
    #     ) or "y_name is not a valid type" not in str(e):
    #         pytest.fail("validation failed")

    # config.name = "global_local_same_name_check"
    # config.x_list.zobject(name="global_local_same_name_check")
    # try:
    #     config.validate()
    # except Exception as e:
    #     pytest.fail("validation failed\n {e}".format(e=e))
